<?xml version="1.0" encoding="utf-8" standalone="no"?>
<test-run id="0" name="TestTask.dll" fullname="D:\projects\TestTask\bin\Debug\net472\TestTask.dll" runstate="Runnable" testcasecount="5" result="Failed" total="5" passed="3" failed="2" inconclusive="0" skipped="0" asserts="3" engine-version="3.12.0.0" clr-version="4.0.30319.42000" start-time="2021-08-04 11:14:05Z" end-time="2021-08-04 11:14:17Z" duration="12.127642">
  <command-line><![CDATA["C:\Program Files (x86)\Microsoft Visual Studio\2019\Enterprise\Common7\IDE\Extensions\TestPlatform\Extensions\..//testhost.net472.x86.exe"  --port 61818 --endpoint 127.0.0.1:061818 --role client --parentprocessid 1232 --telemetryoptedin true]]></command-line>
  <filter>
    <or>
      <test>TestTask.Tests.TestGetArchiveFrames</test>
      <test>TestTask.Tests.TestGetEventsJson</test>
      <test>TestTask.Tests.TestGetTimeJson</test>
      <test>TestTask.Tests.TestGetTimeXml</test>
      <test>TestTask.Tests.TestСonfigexXml</test>
    </or>
  </filter>
  <test-suite type="Assembly" id="0-1006" name="TestTask.dll" fullname="D:\projects\TestTask\bin\Debug\net472\TestTask.dll" runstate="Runnable" testcasecount="5" result="Failed" site="Child" start-time="2021-08-04T11:14:05.8103645Z" end-time="2021-08-04T11:14:17.8746799Z" duration="12.062795" total="5" passed="3" failed="2" warnings="0" inconclusive="0" skipped="0" asserts="3">
    <environment framework-version="3.13.2.0" clr-version="4.0.30319.42000" os-version="Microsoft Windows NT 10.0.19042.0" platform="Win32NT" cwd="C:\Users\User\AppData\Local\Temp" machine-name="LAPTOP-I4MVGP23" user="User" user-domain="LAPTOP-I4MVGP23" culture="ru-RU" uiculture="ru-RU" os-architecture="x86" />
    <settings>
      <setting name="SynchronousEvents" value="False" />
      <setting name="RandomSeed" value="31012377" />
      <setting name="SkipNonTestAssemblies" value="True" />
      <setting name="ProcessModel" value="InProcess" />
      <setting name="DomainUsage" value="Single" />
      <setting name="DefaultTestNamePattern" value="{m}{a}" />
      <setting name="WorkDirectory" value="D:\projects\TestTask\bin\Debug\net472" />
      <setting name="ImageRuntimeVersion" value="4.0.30319" />
      <setting name="ImageTargetFrameworkName" value=".NETFramework,Version=v4.7.2" />
      <setting name="ImageRequiresX86" value="False" />
      <setting name="ImageRequiresDefaultAppDomainAssemblyResolver" value="False" />
      <setting name="TargetRuntimeFramework" value="net-4.0" />
      <setting name="NumberOfTestWorkers" value="8" />
    </settings>
    <properties>
      <property name="_PID" value="15996" />
      <property name="_APPDOMAIN" value="domain-3c4be83b-TestTask.dll" />
    </properties>
    <failure>
      <message><![CDATA[One or more child tests had errors]]></message>
    </failure>
    <test-suite type="TestSuite" id="0-1007" name="TestTask" fullname="TestTask" runstate="Runnable" testcasecount="5" result="Failed" site="Child" start-time="2021-08-04T11:14:05.8423680Z" end-time="2021-08-04T11:14:17.8746799Z" duration="12.032174" total="5" passed="3" failed="2" warnings="0" inconclusive="0" skipped="0" asserts="3">
      <failure>
        <message><![CDATA[One or more child tests had errors]]></message>
      </failure>
      <test-suite type="TestFixture" id="0-1000" name="Tests" fullname="TestTask.Tests" classname="TestTask.Tests" runstate="Runnable" testcasecount="5" result="Failed" site="Child" start-time="2021-08-04T11:14:05.8473672Z" end-time="2021-08-04T11:14:17.8736777Z" duration="12.026845" total="5" passed="3" failed="2" warnings="0" inconclusive="0" skipped="0" asserts="3">
        <failure>
          <message><![CDATA[One or more child tests had errors]]></message>
        </failure>
        <test-case id="0-1002" name="TestGetArchiveFrames" fullname="TestTask.Tests.TestGetArchiveFrames" methodname="TestGetArchiveFrames" classname="TestTask.Tests" runstate="Runnable" seed="621410042" result="Passed" start-time="2021-08-04T11:14:06.0719553Z" end-time="2021-08-04T11:14:07.2876941Z" duration="1.216275" asserts="0" />
        <test-case id="0-1001" name="TestGetEventsJson" fullname="TestTask.Tests.TestGetEventsJson" methodname="TestGetEventsJson" classname="TestTask.Tests" runstate="Runnable" seed="1928208067" result="Failed" label="Error" start-time="2021-08-04T11:14:07.2936942Z" end-time="2021-08-04T11:14:17.4830317Z" duration="10.189433" asserts="0">
          <failure>
            <message><![CDATA[System.Threading.Tasks.TaskCanceledException : Отменена задача.]]></message>
            <stack-trace><![CDATA[   в System.Runtime.CompilerServices.TaskAwaiter.ThrowForNonSuccess(Task task)
   в System.Runtime.CompilerServices.TaskAwaiter.HandleNonSuccessAndDebuggerNotification(Task task)
   в System.Runtime.CompilerServices.TaskAwaiter`1.GetResult()
   в TestTask.Tests.<TestGetEventsJson>d__2.MoveNext() в D:\projects\TestTask\Tests.cs:строка 81
--- Конец трассировка стека из предыдущего расположения, где возникло исключение ---
   в System.Runtime.CompilerServices.TaskAwaiter.ThrowForNonSuccess(Task task)
   в System.Runtime.CompilerServices.TaskAwaiter.HandleNonSuccessAndDebuggerNotification(Task task)
   в System.Runtime.CompilerServices.TaskAwaiter`1.GetResult()
   в NUnit.Framework.Internal.TaskAwaitAdapter.GenericAdapter`1.BlockUntilCompleted()
   в NUnit.Framework.Internal.MessagePumpStrategy.NoMessagePumpStrategy.WaitForCompletion(AwaitAdapter awaiter)
   в NUnit.Framework.Internal.AsyncToSyncAdapter.Await(Func`1 invoke)
   в NUnit.Framework.Internal.Commands.TestMethodCommand.RunTestMethod(TestExecutionContext context)
   в NUnit.Framework.Internal.Commands.TestMethodCommand.Execute(TestExecutionContext context)
   в NUnit.Framework.Internal.Execution.SimpleWorkItem.<>c__DisplayClass4_0.<PerformWork>b__0()
   в NUnit.Framework.Internal.ContextUtils.<>c__DisplayClass1_0`1.<DoIsolated>b__0(Object _)
   в System.Threading.ExecutionContext.RunInternal(ExecutionContext executionContext, ContextCallback callback, Object state, Boolean preserveSyncCtx)
   в System.Threading.ExecutionContext.Run(ExecutionContext executionContext, ContextCallback callback, Object state, Boolean preserveSyncCtx)
   в System.Threading.ExecutionContext.Run(ExecutionContext executionContext, ContextCallback callback, Object state)
   в NUnit.Framework.Internal.ContextUtils.DoIsolated(ContextCallback callback, Object state)
   в NUnit.Framework.Internal.ContextUtils.DoIsolated[T](Func`1 func)
   в NUnit.Framework.Internal.Execution.SimpleWorkItem.PerformWork()]]></stack-trace>
          </failure>
        </test-case>
        <test-case id="0-1004" name="TestGetTimeJson" fullname="TestTask.Tests.TestGetTimeJson" methodname="TestGetTimeJson" classname="TestTask.Tests" runstate="Runnable" seed="57299288" result="Passed" start-time="2021-08-04T11:14:17.4830317Z" end-time="2021-08-04T11:14:17.6437909Z" duration="0.161259" asserts="1" />
        <test-case id="0-1005" name="TestGetTimeXml" fullname="TestTask.Tests.TestGetTimeXml" methodname="TestGetTimeXml" classname="TestTask.Tests" runstate="Runnable" seed="596615452" result="Passed" start-time="2021-08-04T11:14:17.6447754Z" end-time="2021-08-04T11:14:17.6771162Z" duration="0.032923" asserts="1" />
        <test-case id="0-1003" name="TestСonfigexXml" fullname="TestTask.Tests.TestСonfigexXml" methodname="TestСonfigexXml" classname="TestTask.Tests" runstate="Runnable" seed="64148832" result="Failed" start-time="2021-08-04T11:14:17.6771162Z" end-time="2021-08-04T11:14:17.8706955Z" duration="0.193143" asserts="1">
          <failure>
            <message><![CDATA[  Expected: greater than or equal to 6
  But was:  5
]]></message>
            <stack-trace><![CDATA[   в TestTask.Tests.<TestСonfigexXml>d__4.MoveNext() в D:\projects\TestTask\Tests.cs:строка 170
--- Конец трассировка стека из предыдущего расположения, где возникло исключение ---
   в System.Runtime.CompilerServices.TaskAwaiter.ThrowForNonSuccess(Task task)
   в System.Runtime.CompilerServices.TaskAwaiter.HandleNonSuccessAndDebuggerNotification(Task task)
   в System.Runtime.CompilerServices.TaskAwaiter`1.GetResult()
   в NUnit.Framework.Internal.TaskAwaitAdapter.GenericAdapter`1.BlockUntilCompleted()
   в NUnit.Framework.Internal.MessagePumpStrategy.NoMessagePumpStrategy.WaitForCompletion(AwaitAdapter awaiter)
   в NUnit.Framework.Internal.AsyncToSyncAdapter.Await(Func`1 invoke)
   в NUnit.Framework.Internal.Commands.TestMethodCommand.RunTestMethod(TestExecutionContext context)
   в NUnit.Framework.Internal.Commands.TestMethodCommand.Execute(TestExecutionContext context)
   в NUnit.Framework.Internal.Execution.SimpleWorkItem.<>c__DisplayClass4_0.<PerformWork>b__0()
   в NUnit.Framework.Internal.ContextUtils.<>c__DisplayClass1_0`1.<DoIsolated>b__0(Object _)
]]></stack-trace>
          </failure>
          <assertions>
            <assertion result="Failed">
              <message><![CDATA[  Expected: greater than or equal to 6
  But was:  5
]]></message>
              <stack-trace><![CDATA[   в TestTask.Tests.<TestСonfigexXml>d__4.MoveNext() в D:\projects\TestTask\Tests.cs:строка 170
   в System.Runtime.CompilerServices.AsyncMethodBuilderCore.MoveNextRunner.InvokeMoveNext(Object stateMachine)
]]></stack-trace>
            </assertion>
          </assertions>
        </test-case>
      </test-suite>
    </test-suite>
  </test-suite>
</test-run>